export const description = 'Error reference for the Inngest TypeScript SDK'

# Errors

Inngest automatically handles errors and retries for you. You can use standard errors or use included Inngest errors to control how Inngest handles errors.

Read more about the approaches to [handling errors in our guide](/docs/guides/error-handling).

## Standard errors

All `Error` objects are handled by Inngest and [retried automatically](/docs/guides/error-handling#retries). This includes all standard errors like `TypeError` and custom errors that extend the `Error` class. You can throw errors in the function handler or within a step.

```typescript
export default inngest.createFunction(
  { id: "import-item-data" },
  { event: "store/import.requested" },
  async ({ event }) => {

    // throwing a standard error
    if (!event.itemId) {
      throw new Error("Item ID is required");
    }

    // throwing an error within a step
    const item = await step.run('fetch-item', async () => {
      const response = await fetch(`https://api.ecommerce.com/items/${event.itemId}`);
      if (response.status === 500) {
        throw new Error("Failed to fetch item from ecommerce API");
      }
      // ...
    });
  }
);
```

## `NonRetriableError`

Use `NonRetriableError` to prevent Inngest from retrying the function _or_ step. This is useful when the type of error is not expected to be resolved by a retry, for example, when the error is caused by an invalid input or when the error is expected to occur again if retried.

```typescript
import { NonRetriableError } from "inngest";

export default inngest.createFunction(
  { id: "mark-store-imported" },
  { event: "store/import.completed" },
  async ({ event }) => {
    try {
      const result = await database.updateStore(
        { id: event.data.storeId },
        { imported: true }
      );
      return result.ok === true;
    } catch (err) {
      // Passing the original error via `cause` enables you to view the error in function logs
      throw new NonRetriableError("Store not found", { cause: err });
    }
  }
);
```

### Parameters

```ts
new NonRetriableError(message: string, options?: { cause?: Error }): NonRetriableError
```

<Properties>
  <Property name="message" type="string" required>
    The error message.
  </Property>
  <Property name="options" type="object">
    <Properties nested={true} collapse={true}>
      <Property name="cause" type="Error">
        The original error that caused the non-retriable error.
      </Property>
    </Properties>
  </Property>
</Properties>

## `RetryAfterError`

Use `RetryAfterError` to control when Inngest should retry the function or step. This is useful when you want to delay the next retry attempt for a specific period of time, for example, to more gracefully handle a race condition or backing off after hitting an API rate limit.

If `RetryAfterError` is not used, Inngest will use [the default retry backoff policy](https://github.com/inngest/inngest/blob/main/pkg/backoff/backoff.go#L10-L22).

```typescript
inngest.createFunction(
  { id: "send-welcome-sms" },
  { event: "app/user.created" },
  async ({ event, step }) => {
    const { success, retryAfter } = await twilio.messages.create({
      to: event.data.user.phoneNumber,
      body: "Welcome to our service!",
    });

    if (!success && retryAfter) {
      throw new RetryAfterError("Hit Twilio rate limit", retryAfter);
    }
  }
);
```

### Parameters

```ts
new RetryAfterError(
  message: string,
  retryAfter: number | string | date,
  options?: { cause?: Error }
): RetryAfterError
```

<Properties>
  <Property name="message" type="string" required>
    The error message.
  </Property>
  <Property name="retryAfter" type="number | string | date" required>
    The specified time to delay the next retry attempt. The following formats are accepted:

    * `number` - The number of **seconds** to delay the next retry attempt.
    * `string` - A time string, parsed by the [ms](https://npm.im/ms) package, such as `"30m"`, `"3 hours"`, or `"2.5d"`.
    * `date` - A `Date` object.
  </Property>
  <Property name="options" type="object">
    <Properties nested={true} collapse={true}>
      <Property name="cause" type="Error">
        The original error that caused the non-retriable error.
      </Property>
    </Properties>
  </Property>
</Properties>

## Step errors <VersionBadge version="v3.12.0+" />

After a step exhausts all of its retries, it will throw a `StepError` which can be caught and handled in the function handler if desired.

<CodeGroup>
```ts {{ title: "try/catch" }}
inngest.createFunction(
  { id: "send-weather-forecast" },
  { event: "weather/forecast.requested" },
  async ({ event, step }) => {
    let data;

    try {
      data = await step.run('get-public-weather-data', async () => {
        return await fetch('https://api.weather.com/data');
      });
    } catch (err) {
      // err will be an instance of StepError
      // Handle the error by recovering with a different step
      data = await step.run('use-backup-weather-api', async () => {
        return await fetch('https://api.stormwaters.com/data');
      });
    }
    // ...
  }
);
```
```ts {{ title: "Chaining with .catch()" }}
inngest.createFunction(
  { id: "send-weather-forecast" },
  { event: "weather/forecast.requested" },
  async ({ event, step }) => {

    const data = await step
      .run('get-public-weather-data', async () => {
        return await fetch('https://api.example.com/data');
      })
      .catch((err) => {
        // err will be an instance of StepError
        // Recover with a chained step
        return step.run("use-backup-weather-api", () => {
          return await fetch('https://api.stormwaters.com/data');
        });
      });
  }
);
```
```ts {{ title: "Ignoring and logging the error" }}
inngest.createFunction(
  { id: "send-weather-forecast" },
  { event: "weather/forecast.requested" },
  async ({ event, step }) => {

    const data = await step
      .run('get-public-weather-data', async () => {
        return await fetch('https://api.example.com/data');
      })
      // This will swallow the error and log it if it's non critical
      .catch((err) => logger.error(err));
  }
);
```
</CodeGroup>

<Callout>
  Support for handling step errors is available in the Inngest TypeScript SDK starting from version **3.12.0**. Prior to this version, wrapping a step in try/catch will not work correctly.
</Callout>

## Attempt counter

The current attempt number is passed in as input to the function handler. `attempt` is a zero-index number that increments for each retry. The first attempt will be `0`, the second `1`, and so on. The number is reset after a successfully executed step.

```ts
inngest.createFunction(
  { id: "generate-summary" },
  { event: "blog/post.created" },
  async ({ attempt }) => {
    // `attempt` is the zero-index attempt number

    await step.run('call-llm', async () => {
      if (attempt < 2) {
        // Call OpenAI's API two times
      } else {
        // After two attempts to OpenAI, try a different LLM, for example, Mistral
      }
    });
  }
);
```

## Learn more

* Guide: [Error handling](/docs/guides/error-handling)
* TypeScript SDK Reference: [`onFailure`](/docs/reference/functions/handling-failures)




